cuda
2022-11-21 13:22:34,653 - root - INFO - Task Started
2022-11-21 13:22:34,653 - root - INFO - [1/1] Data Preparing - Start
Traceback (most recent call last):
  File "train2.py", line 65, in <module>
    main()
  File "train2.py", line 24, in main
    train_data, valid_data, test_data, n_node, feature_input_dims = prepare_dataset(
TypeError: prepare_dataset() got multiple values for argument 'verbose'