2022-11-23 08:02:04,658 INFO    MainThread:91090 [wandb_setup.py:_flush():68] Configure stats pid to 91090
2022-11-23 08:02:04,658 INFO    MainThread:91090 [wandb_setup.py:_flush():68] Loading settings from /opt/ml/.config/wandb/settings
2022-11-23 08:02:04,658 INFO    MainThread:91090 [wandb_setup.py:_flush():68] Loading settings from /opt/ml/input/code/dkt/wandb/settings
2022-11-23 08:02:04,658 INFO    MainThread:91090 [wandb_setup.py:_flush():68] Loading settings from environment variables: {'_require_service': 'True'}
2022-11-23 08:02:04,659 INFO    MainThread:91090 [wandb_setup.py:_flush():68] Inferring run settings from compute environment: {'program': '<python with no main file>'}
2022-11-23 08:02:04,659 ERROR   MainThread:91090 [wandb_setup.py:_flush():68] error
Traceback (most recent call last):
  File "/opt/conda/envs/dkt/lib/python3.8/site-packages/wandb/sdk/wandb_init.py", line 1075, in init
    wi.setup(kwargs)
  File "/opt/conda/envs/dkt/lib/python3.8/site-packages/wandb/sdk/wandb_init.py", line 219, in setup
    init_config = parse_config(
  File "/opt/conda/envs/dkt/lib/python3.8/site-packages/wandb/sdk/wandb_helper.py", line 14, in parse_config
    params = _to_dict(params)
  File "/opt/conda/envs/dkt/lib/python3.8/site-packages/wandb/sdk/wandb_helper.py", line 42, in _to_dict
    raise TypeError("config must be a dict or have a __dict__ attribute.")
TypeError: config must be a dict or have a __dict__ attribute.
2022-11-23 08:02:04,659 ERROR   MainThread:91090 [wandb_setup.py:_flush():68] error
Traceback (most recent call last):
  File "/opt/conda/envs/dkt/lib/python3.8/site-packages/wandb/sdk/wandb_init.py", line 1075, in init
    wi.setup(kwargs)
  File "/opt/conda/envs/dkt/lib/python3.8/site-packages/wandb/sdk/wandb_init.py", line 219, in setup
    init_config = parse_config(
  File "/opt/conda/envs/dkt/lib/python3.8/site-packages/wandb/sdk/wandb_helper.py", line 14, in parse_config
    params = _to_dict(params)
  File "/opt/conda/envs/dkt/lib/python3.8/site-packages/wandb/sdk/wandb_helper.py", line 42, in _to_dict
    raise TypeError("config must be a dict or have a __dict__ attribute.")
TypeError: config must be a dict or have a __dict__ attribute.
2022-11-23 08:02:04,659 ERROR   MainThread:91090 [wandb_setup.py:_flush():68] error
Traceback (most recent call last):
  File "/opt/conda/envs/dkt/lib/python3.8/site-packages/wandb/sdk/wandb_init.py", line 1075, in init
    wi.setup(kwargs)
  File "/opt/conda/envs/dkt/lib/python3.8/site-packages/wandb/sdk/wandb_init.py", line 219, in setup
    init_config = parse_config(
  File "/opt/conda/envs/dkt/lib/python3.8/site-packages/wandb/sdk/wandb_helper.py", line 14, in parse_config
    params = _to_dict(params)
  File "/opt/conda/envs/dkt/lib/python3.8/site-packages/wandb/sdk/wandb_helper.py", line 42, in _to_dict
    raise TypeError("config must be a dict or have a __dict__ attribute.")
TypeError: config must be a dict or have a __dict__ attribute.
2022-11-23 08:02:04,659 ERROR   MainThread:91090 [wandb_setup.py:_flush():68] error
Traceback (most recent call last):
  File "/opt/conda/envs/dkt/lib/python3.8/site-packages/wandb/sdk/wandb_init.py", line 1075, in init
    wi.setup(kwargs)
  File "/opt/conda/envs/dkt/lib/python3.8/site-packages/wandb/sdk/wandb_init.py", line 219, in setup
    init_config = parse_config(
  File "/opt/conda/envs/dkt/lib/python3.8/site-packages/wandb/sdk/wandb_helper.py", line 14, in parse_config
    params = _to_dict(params)
  File "/opt/conda/envs/dkt/lib/python3.8/site-packages/wandb/sdk/wandb_helper.py", line 42, in _to_dict
    raise TypeError("config must be a dict or have a __dict__ attribute.")
TypeError: config must be a dict or have a __dict__ attribute.
2022-11-23 08:02:04,659 ERROR   MainThread:91090 [wandb_setup.py:_flush():68] error
Traceback (most recent call last):
  File "/opt/conda/envs/dkt/lib/python3.8/site-packages/wandb/sdk/wandb_init.py", line 1075, in init
    wi.setup(kwargs)
  File "/opt/conda/envs/dkt/lib/python3.8/site-packages/wandb/sdk/wandb_init.py", line 219, in setup
    init_config = parse_config(
  File "/opt/conda/envs/dkt/lib/python3.8/site-packages/wandb/sdk/wandb_helper.py", line 14, in parse_config
    params = _to_dict(params)
  File "/opt/conda/envs/dkt/lib/python3.8/site-packages/wandb/sdk/wandb_helper.py", line 42, in _to_dict
    raise TypeError("config must be a dict or have a __dict__ attribute.")
TypeError: config must be a dict or have a __dict__ attribute.
2022-11-23 08:02:04,659 ERROR   MainThread:91090 [wandb_setup.py:_flush():68] error
Traceback (most recent call last):
  File "/opt/conda/envs/dkt/lib/python3.8/site-packages/wandb/sdk/wandb_init.py", line 1075, in init
    wi.setup(kwargs)
  File "/opt/conda/envs/dkt/lib/python3.8/site-packages/wandb/sdk/wandb_init.py", line 219, in setup
    init_config = parse_config(
  File "/opt/conda/envs/dkt/lib/python3.8/site-packages/wandb/sdk/wandb_helper.py", line 14, in parse_config
    params = _to_dict(params)
  File "/opt/conda/envs/dkt/lib/python3.8/site-packages/wandb/sdk/wandb_helper.py", line 42, in _to_dict
    raise TypeError("config must be a dict or have a __dict__ attribute.")
TypeError: config must be a dict or have a __dict__ attribute.
2022-11-23 08:02:04,659 INFO    MainThread:91090 [wandb_init.py:_log_setup():476] Logging user logs to /opt/ml/input/code/dkt/wandb/run-20221123_080204-3ry2o92w/logs/debug.log
2022-11-23 08:02:04,659 INFO    MainThread:91090 [wandb_init.py:_log_setup():477] Logging internal logs to /opt/ml/input/code/dkt/wandb/run-20221123_080204-3ry2o92w/logs/debug-internal.log
2022-11-23 08:02:04,660 INFO    MainThread:91090 [wandb_init.py:init():516] calling init triggers
2022-11-23 08:02:04,660 INFO    MainThread:91090 [wandb_init.py:init():519] wandb.init called with sweep_config: {}
config: {}
2022-11-23 08:02:04,660 INFO    MainThread:91090 [wandb_init.py:init():569] starting backend
2022-11-23 08:02:04,660 INFO    MainThread:91090 [wandb_init.py:init():573] setting up manager
2022-11-23 08:02:04,661 INFO    MainThread:91090 [backend.py:_multiprocessing_setup():102] multiprocessing start_methods=fork,spawn,forkserver, using: spawn
2022-11-23 08:02:04,662 INFO    MainThread:91090 [wandb_init.py:init():580] backend started and connected
2022-11-23 08:02:04,676 INFO    MainThread:91090 [wandb_run.py:_label_probe_notebook():1113] probe notebook
2022-11-23 08:02:04,676 INFO    MainThread:91090 [wandb_run.py:_label_probe_notebook():1123] Unable to probe notebook: 'NoneType' object has no attribute 'get'
2022-11-23 08:02:04,676 INFO    MainThread:91090 [wandb_init.py:init():658] updated telemetry
2022-11-23 08:02:04,677 INFO    MainThread:91090 [wandb_init.py:init():693] communicating run to backend with 60 second timeout
2022-11-23 08:02:05,780 INFO    MainThread:91090 [wandb_run.py:_on_init():2000] communicating current version
2022-11-23 08:02:06,327 WARNING MsgRouterThr:91090 [router.py:_handle_msg_rcv():114] No listener found for msg with uuid f92fb1aefa444d73b0398630ba018ece (control {
  req_resp: true
  local: true
  relay_id: "b5747cfd95fb4462aca859105605f270"
}
uuid: "f92fb1aefa444d73b0398630ba018ece"
)
2022-11-23 08:02:10,781 INFO    MainThread:91090 [wandb_run.py:_on_init():2004] got version response None
2022-11-23 08:02:10,781 INFO    MainThread:91090 [wandb_init.py:init():728] starting run threads in backend
2022-11-23 08:02:15,799 INFO    MainThread:91090 [wandb_run.py:_console_start():1980] atexit reg
2022-11-23 08:02:15,799 INFO    MainThread:91090 [wandb_run.py:_redirect():1838] redirect: SettingsConsole.WRAP_RAW
2022-11-23 08:02:15,799 INFO    MainThread:91090 [wandb_run.py:_redirect():1903] Wrapping output streams.
2022-11-23 08:02:15,800 INFO    MainThread:91090 [wandb_run.py:_redirect():1925] Redirects installed.
2022-11-23 08:02:15,800 INFO    MainThread:91090 [wandb_init.py:init():765] run started, returning control to user process
2022-11-23 08:02:21,390 WARNING MsgRouterThr:91090 [router.py:message_loop():77] message_loop has been closed
2022-11-23 08:02:56,931 WARNING MsgRouterThr:91090 [router.py:message_loop():77] message_loop has been closed
